Workbook

Sheet Table
E5: Single Phase
E6: Three Phase
B11: Unit ID | C11: EHO Number | D11: Dimensions | E11: Power Req. | F11: Unit ID | G11: EHO Number | H11: Dimensions | I11: Power Req.
D12: L x W | H12: L x W
B13: Burger/Chipper Units | F13: Confectionery
B14: O'Briens Chipper 1 | C14: 76575 | D14: 6M x 3M | E14: 125A + 32A | F14: Off Beat Donuts 2 | H14: 5M x 3M | I14: 32A + 16A
B15: O'Briens Chipper 2 | C15: 76967 | D15: 4M x 3M | E15: 63A | F15: Off Beat Donuts | G15: 76964 | H15: 5M x 3M | I15: 32A x2
B16: Smash Burger 1 | C16: 76972 | D16: 5M x 3M | E16: 125A | F16: Chocolate Fountain | G16: 76971 | H16: 4M x 3M | I16: 32A x2
B17: Smash Burger 2 | D17: 5M x 3M | E17: 125A | F17: Pick'n'Mix | H17: 5M x 3M | I17: 32A
B18: Loaded Burger | C18: 88122 | D18: 5.5M x 3M | E18: 125A | F18: The Village Kiosk 1 | G18: 76970 | H18: 4M x 3M | I18: 32A
B19: Misc. Food Units | F19: The Village Kiosk 2 | G19: 81824 | H19: 4M x 3M | I19: 16A
B20: Flex Use Airstream | D20: 5M x 3M | E20: 63A | F20: Sprinkles Churros | H20: 5M x 3M | I20: 32A
B21: Angelo's Pizza | C21: 76968 | D21: 4M x 3M | E21: 32A | F21: Sprinkles Desserts | G21: 98859 | H21: 4M x 3M | I21: 63A + 32A
B22: Angelo's Pizza & Pasta | C22: 88124 | D22: 9M x 3M | E22: 63A | F22: Ice Cream Vans
B23: Fried Chicken Truck | C23: 30923 | D23: 6M x 3M | E23: 63A | F23: 231-D | G23: 118984 | H23: 5M x 3M | I23: 32A + 13A
B24: Thindi | C24: 16535 | D24: 5M x 3M | E24: 63A | F24: 201-D | G24: 118985 | H24: 5M x 3M | I24: 32A + 13A
B25: Toasted | C25: 76963 | D25: 4M x 3M | E25: 63A | F25: 152-D | G25: 81822 | H25: 5M x 3M | I25: 32A + 13A
B26: Bun Club Hot Dogs | C26: 76966 | D26: 5M x 3M | E26: 63A | F26: 142-D | G26: 75724 | H26: 5M x 3M | I26: 32A + 13A
B27: Zambrero | C27: 113714 | D27: 6M x 3M | E27: 63A | F27: 09-D | G27: 76925 | H27: 5M x 3M | I27: 32A + 13A
B28: Pitt Bros BBQ | C28: 81939 | D28: 5M x 3M | E28: 63A | F28: 07-D | G28: 76926 | H28: 4M x 3M | I28: 32A + 13A
B29: Lucky Bao Buns | C29: 100979 | D29: 6M x 3M | E29: 32A | F29: 07-RN | G29: 76924 | H29: 5M x 3M | I29: 32A + 13A
B30: Camile Thai 2.0 | C30: 100979 | D30: 6M x 3M | E30: 125A | F30: 05-D | G30: 76922 | H30: 5M x 3M | I30: 13A
B31: Camile Thai | C31: 91759 | D31: 6M x 3M | E31: 125A | F31: 05-WH | G31: 81936 | H31: 5M x 3M | I31: 13A
B32: Coffee/Beverages | F32: 04-D | G32: 76927 | H32: 4M x 3M | I32: 13A
B33: Caffe Duomo 1 | C33: 88120 | D33: 5M x 3M | E33: 32A | F33: 03-D | G33: 76957 | H33: 4M x 3M | I33: 13A
B34: Caffe Duomo 2 | C34: 76961 | D34: 3M x 3M | E34: 32A x2 | F34: 02-WW | G34: 76956 | H34: 5M x 3M | I34: 13A
B35: Caffe Duomo 3 | D35: 3M x 3M | E35: 32A x2 | F35: 02-C | G35: 76959 | H35: 5M x 3M | I35: 13A
B36: Caffe Duomo Van | D36: 5M x 3M | E36: 32A | F36: 01-D | G36: 76960 | H36: 5M x 3M | I36: 13A
B37: Caffe Duomo/Torelli | C37: 76962 | D37: 4M x 3M | E37: 32A x2 | F37: BMC | G37: 76973 | H37: 6M x 3M | I37: 32A + 13A
B38: Freshly Ground Coffee 1 | D38: 3M x 3M | E38: 32A x2 | F38: LD | G38: 78576 | H38: 4M x 3M | I38: 32A + 13A
B39: Freshly Ground Coffee 2 | D39: 4M x 3M | E39: 32A x2 | F39: Pink Bedford | G39: 81823 | H39: 4M x 3M | I39: 32A + 13A
B40: Smoothies & Shakes 1 | C40: 76965 | D40: 5M x 3M | E40: 32A | F40: Yellow Transit | G40: 81935 | H40: 4M x 3M | I40: 32A + 13A
B41: Nobo/Citroen | D41: 4M x 3M | E41: 32A | F41: 88-WX | H41: 6M x 3M | I41: 16A + 13A
F42: Carts & Trikes
F43: Camile Cart | H43: 2M x 3M | I43: 16A
F44: Zambrero Cart | H44: 2M x 3M | I44: 16A
F45: Vespa Cart #1 | H45: 2M x 3M | I45: 13A
F46: Vespa Cart #2 | H46: 2M x 3M | I46: 13A
F47: Sweet Cart | H47: 2M x 3M | I47: 13A

Sheet Live Ops Checklist
B1: 🚚 | C1: 🅿️ | D1: 🧼 | E1: ⚡️ | F1: 📠 | G1: 🧾 | H1: 🌡 | I1: 🧯
A2: Friday
A3: Ideal Homes (Fri-Sunday) | B3: FALSE | C3: FALSE | D3: FALSE | E3: FALSE | F3: FALSE | G3: FALSE | H3: FALSE | I3: FALSE
A4: Camile | B4: FALSE | C4: FALSE | D4: FALSE | E4: TRUE | F4: FALSE | G4: FALSE | H4: FALSE | I4: FALSE
A5: Off Beat | B5: TRUE | C5: TRUE | D5: FALSE | E5: TRUE | F5: TRUE | G5: FALSE | H5: FALSE | I5: FALSE
A6: Toasted | B6: TRUE | C6: FALSE | D6: FALSE | E6: TRUE | F6: FALSE | G6: FALSE | H6: FALSE | I6: FALSE
A7: Coffee | B7: TRUE | C7: TRUE | D7: FALSE | E7: TRUE | F7: TRUE | G7: FALSE | H7: FALSE | I7: FALSE
A9: Saturday | B9: FALSE | C9: FALSE | D9: FALSE | E9: FALSE | F9: FALSE | G9: FALSE | H9: FALSE | I9: FALSE
A10: Merrion Square (Sat-Sun) | B10: FALSE | C10: FALSE | D10: FALSE | E10: FALSE | F10: FALSE | G10: FALSE | H10: FALSE | I10: FALSE
A11: Coffee | B11: FALSE | C11: FALSE | D11: FALSE | E11: FALSE | F11: FALSE | G11: FALSE | H11: FALSE | I11: FALSE
A12: Ice Cream | B12: FALSE | C12: FALSE | D12: FALSE | E12: FALSE | F12: FALSE | G12: FALSE | H12: FALSE | I12: FALSE
A13: Ice Cream | B13: FALSE | C13: FALSE | D13: FALSE | E13: FALSE | F13: FALSE | G13: FALSE | H13: FALSE | I13: FALSE
A14: Fairyhouse (Sat Only) | B14: FALSE | C14: FALSE | D14: FALSE | E14: FALSE | F14: FALSE | G14: FALSE | H14: FALSE | I14: FALSE
A15: Coffee | B15: TRUE | C15: FALSE | D15: FALSE | E15: FALSE | F15: FALSE | G15: FALSE | H15: FALSE | I15: FALSE
... A38: 142-D Van | B38: FALSE | C38: FALSE | D38: FALSE | E38: FALSE | F38: FALSE | G38: FALSE | H38: FALSE | I38: FALSE

Sheet Sheet25

Sheet Punchestown Festival 26
B1: Punchestown Festival 2024
K2: Last Year | L2: FC | M2: Cash | N2: Card | O2: Total | P2: Last Year | Q2: FC | R2: Cash | S2: Card | T2: Total | U2: Last Year | V2: FC | W2: Cash | X2: Card | Y2: Total | Z2: Last Year | AA2: FC | AB2: Cash | AC2: Card | AD2: Total | AE2: Last Year | AF2: FC | AG2: Cash | AH2: Card | AI2: Total
A3: Units | B3: Location | C3: 🚚 | D3: 🅿️ | E3: 🧼 | F3: ⚡️ | G3: 📠 | H3: 🧾 | I3: 🌡 | J3: 🧯 | K3: Tuesday | P3: Wednesday | U3: Thursday | Z3: Friday | AE3: Saturday
A4: Caffe Duomo Trailer | B4: Parade Ring | C4: FALSE | D4: FALSE | E4: FALSE | F4: FALSE | G4: FALSE | H4: FALSE | I4: FALSE | J4: FALSE | O4: =SUM(M4, N4) -> 0 | T4: =SUM(R4, S4) -> 0 | Y4: =SUM(W4:X4) -> 0 | AD4: =SUM(AB4:AC4) -> 0 | AI4: =SUM(AG4:AH4) -> 0
A5: Caffe Duomo Trailer | B5: Parade Ring | C5: FALSE | D5: FALSE | E5: FALSE | F5: FALSE | G5: FALSE | H5: FALSE | I5: FALSE | J5: FALSE | O5: =SUM(M5, N5) -> 0 | T5: =SUM(R5, S5) -> 0 | Y5: =SUM(W5:X5) -> 0 | AD5: =SUM(AB5:AC5) -> 0 | AI5: =SUM(AG5:AH5) -> 0
A6: Off Beat | B6: Parade Ring | C6: FALSE | D6: FALSE | E6: FALSE | F6: FALSE | G6: FALSE | H6: FALSE | I6: FALSE | J6: FALSE | O6: =SUM(M6, N6) -> 0 | T6: =SUM(R6, S6) -> 0 | Y6: =SUM(W6:X6) -> 0 | AD6: =SUM(AB6:AC6) -> 0 | AI6: =SUM(AG6:AH6) -> 0
A7: Kiosk Trailer | B7: Parade Ring | C7: FALSE | D7: FALSE | E7: FALSE | F7: FALSE | G7: FALSE | H7: FALSE | I7: FALSE | J7: FALSE | O7: =SUM(M7, N7) -> 0 | T7: =SUM(R7, S7) -> 0 | Y7: =SUM(W7:X7) -> 0 | AD7: =SUM(AB7:AC7) -> 0 | AI7: =SUM(AG7:AH7) -> 0
A8: Toasted | B8: Ladbrokes | C8: FALSE | D8: FALSE | E8: FALSE | F8: FALSE | G8: FALSE | H8: FALSE | I8: FALSE | J8: FALSE | O8: =SUM(M8:N8) -> 0 | T8: =SUM(R8:S8) -> 0 | Y8: =SUM(W8:X8) -> 0 | AD8: =SUM(AB8:AC8) -> 0 | AI8: =SUM(AG8:AH8) -> 0
A9: Camile | B9: Ladbrokes | C9: FALSE | D9: FALSE | E9: FALSE | F9: FALSE | G9: FALSE | H9: FALSE | I9: FALSE | J9: FALSE | O9: =SUM(M9:N9) -> 0 | T9: =SUM(R9:S9) -> 0 | Y9: =SUM(W9:X9) -> 0 | AD9: =SUM(AB9:AC9) -> 0 | AI9: =SUM(AG9:AH9) -> 0
A10: Pitt Bros | B10: Sky Bar | C10: FALSE | D10: FALSE | E10: FALSE | F10: FALSE | G10: FALSE | H10: FALSE | I10: FALSE | J10: FALSE | O10: =SUM(M10:N10) -> 0 | T10: =SUM(R10:S10) -> 0 | Y10: =SUM(W10:X10) -> 0 | AD10: =SUM(AB10:AC10) -> 0 | AI10: =SUM(AG10:AH10) -> 0
A11: Loaded | B11: Sky Bar | C11: FALSE | D11: FALSE | E11: FALSE | F11: FALSE | G11: FALSE | H11: FALSE | I11: FALSE | J11: FALSE | O11: =SUM(M11:N11) -> 0 | T11: =SUM(R11:S11) -> 0 | Y11: =SUM(W11:X11) -> 0 | AD11: =SUM(AB11:AC11) -> 0 | AI11: =SUM(AG11:AH11) -> 0
A12: Smash | B12: Sky Bar | C12: FALSE | D12: FALSE | E12: FALSE | F12: FALSE | G12: FALSE | H12: FALSE | I12: FALSE | J12: FALSE | O12: =SUM(M12:N12) -> 0 | T12: =SUM(R12:S12) -> 0 | Y12: =SUM(W12:X12) -> 0 | AD12: =SUM(AB12:AC12) -> 0 | AI12: =SUM(AG12:AH12) -> 0
A13: Ice Cream | B13: Parade Ring | C13: FALSE | D13: FALSE | E13: FALSE | F13: FALSE | G13: FALSE | H13: FALSE | I13: FALSE | J13: FALSE | O13: =SUM(M13:N13) -> 0 | T13: =SUM(R13:S13) -> 0 | Y13: =SUM(W13:X13) -> 0 | AD13: =SUM(AB13:AC13) -> 0 | AI13: =SUM(AG13:AH13) -> 0
A14: Ice Cream | B14: Parade Ring | C14: FALSE | D14: FALSE | E14: FALSE | F14: FALSE | G14: FALSE | H14: FALSE | I14: FALSE | J14: FALSE | O14: =SUM(M14:N14) -> 0 | T14: =SUM(R14:S14) -> 0 | Y14: =SUM(W14:X14) -> 0 | AD14: =SUM(AB14:AC14) -> 0 | AI14: =SUM(AG14:AH14) -> 0
A15: Ice Cream | B15: Sky Bar | C15: FALSE | D15: FALSE | E15: FALSE | F15: FALSE | G15: FALSE | H15: FALSE | I15: FALSE | J15: FALSE | O15: =SUM(M15:N15) -> 0 | T15: =SUM(R15:S15) -> 0 | Y15: =SUM(W15:X15) -> 0 | AD15: =SUM(AB15:AC15) -> 0 | AI15: =SUM(AG15:AH15) -> 0
A16: Electric Van | C16: FALSE | D16: FALSE | E16: FALSE | F16: FALSE | G16: FALSE | H16: FALSE | I16: FALSE | J16: FALSE | O16: =SUM(M16:N16) -> 0 | T16: =SUM(R16:S16) -> 0 | Y16: =SUM(W16:X16) -> 0 | AD16: =SUM(AB16:AC16) -> 0 | AI16: =SUM(AG16:AH16) -> 0
A17: 142-D Van | C17: FALSE | D17: FALSE | E17: FALSE | F17: FALSE | G17: FALSE | H17: FALSE | I17: FALSE | J17: FALSE | O17: =SUM(M17:N17) -> 0 | T17: =SUM(R17:S17) -> 0 | Y17: =SUM(W17:X17) -> 0 | AD17: =SUM(AB17:AC17) -> 0 | AI17: =SUM(AG17:AH17) -> 0
A18: Daily Total | K18: =SUM(K4:K17) -> 0 | L18: =SUM(L4:L17) -> 0 | M18: =SUM(M4:M17) -> 0 | N18: =SUM(N4:N17) -> 0 | O18: =SUM(O4:O17) -> 0 | P18: =SUM(P4:P17) -> 0 | Q18: =SUM(Q4:Q17) -> 0 | R18: =SUM(R4:R17) -> 0 | ... AI18: =SUM(AI4:AI17) -> 0
Z19: Zambrero | AD19: =SUM(AB19:AC19) -> 0 | AI19: =SUM(AG19:AH19) -> 0
A20: Overall Total | Z20: Off Beat | AD20: =SUM(AB20:AC20) -> 0 | AI20: =SUM(AG20:AH20) -> 0
A21: =SUM(O18, T18, Y18, AD18, AI18) -> 0 | Z21: Van Carnival | AD21: =SUM(AB21:AC21) -> 0 | AI21: =SUM(AG21:AH21) -> 0
Z22: Van Carnival | AD22: =SUM(AB22:AC22) -> 0 | AI22: =SUM(AG22:AH22) -> 0
A23: Vs Last Year | AC23: Total | AD23: =SUM(AD18:AD22) -> 0 | AH23: Total | AI23: =SUM(AI18:AI22) -> 0
A24: =SUM(K18, P18, U18, Z18, AE18) -> 0
D28: Staff | E28: Number | F28: Name | G28: Number
F29: Shannon
F30: Katelyn
F31: Lauren
F32: Megan
F33: Sam
F34: Megan
F35: Sean
F36: Nicola
F37: Nicola
F38: Leon
F39: Ann
F40: Amanda
... F58: Troy

Sheet Fairyhouse Grand National 
A2: Unit ID | B2: EHO Number | C2: Dimensions | D2: Power Req. | E2: Location (Currently) | F2: Vehicle & Run | G2: Driver | H2: Day
C3: L x W
A4: Loaded Burger | B4: 88122 | C4: 5.5M x 3M | D4: 125A | E4: Leopardstown | F4: INEOS 3 | G4: Tom | H4: Tuesday
A5: Thindi | B5: 16535 | C5: 5M x 3M | D5: 63A | E5: RDS | F5: 1 | G5: Serg | H5: Monday
A6: Toasted | B6: 76963 | C6: 4M x 3M | D6: 32A | E6: RDS | F6: Sprinter Fridge 2 | G6: Simon | H6: Monday
A7: Caffe Duomo 1 | B7: 88120 | C7: 5M x 3M | D7: 32A | E7: RDS | F7: Transit 1 | G7: Robo | H7: Monday
A8: Caffe Duomo 2 | B8: 76961 | C8: 3M x 3M | D8: 32A | E8: RDS | F8: Transit 3 | G8: Robo | H8: Monday
A9: Off Beat Donuts | B9: 76964 | C9: 5M x 3M | D9: 32A | E9: RDS | F9: INEOS 1 | G9: Simon | H9: Monday
A10: Pitt Bros BBQ | B10: 81939 | C10: 5M x 3M | D10: 63A | E10: RDS | F10: Custom 2 | G10: Kian | H10: Monday
A11: Fried Chicken Truck | B11: 30923 | C11: 6M x 3M | D11: 125A | E11: Unit | G11: Serg | H11: Monday
A12: Pink Bedford | B12: 81823 | C12: 4M x 3M | D12: 32A | E12: Unit | G12: Serg | H12: Tuesday
A13: Smash Burger 1 | B13: 76972 | C13: 5M x 3M | D13: 125A | E13: Punchestown | F13: Transit 3 | G13: Robo | H13: Tuesday
A14: Sprinkles Churros | B14: 98859 | C14: 5M x 3M | D14: 32A | E14: RDS | F14: INEOS 2 | G14: Tom | H14: Monday
A15: BMC | B15: 76973 | C15: 6M x 3M | D15: 32A + 13A | E15: Unit | G15: Serg | H15: Tuesday
A16: Caffe Duomo/Vintage | B16: 76962 | C16: 4M x 3M | D16: 32A x2 | E16: RDS | F16: Tow Truck 1 | G16: Tom | H16: Monday
A17: The Village Kiosk 1 | B17: 76970 | C17: 4M x 3M | D17: 32A | E17: RDS | F17: Drive on 1 | G17: Kian | H17: Monday
A18: The Village Kiosk 2 | B18: 81824 | C18: 4M x 3M | D18: 16A | E18: RDS | F18: Drive on 1 | G18: Kian | H18: Monday

Sheet DRF 26
A1: DRF 2025 | I1: Stock & Orders
A2: Stall/Unit Name | B2: Location | C2: 🅿️ | D2: 🧽 | E2: ⚡️ | F2: 💻 | G2: 🧯 | H2: 👥 | I2: Sysco | J2: Camile | K2: ReadyChef | L2: BWG | M2: Pitt Bros | N2: Sandwiches | O2: Bretzel
A3: Caffe Duomo | B3: Outside Gates | C3: FALSE | D3: FALSE | E3: FALSE | F3: FALSE | G3: FALSE | H3: FALSE | I3: TRUE | J3: TRUE | K3: FALSE | L3: FALSE | M3: TRUE | N3: FALSE | O3: TRUE
A4: toasted | B4: Marquee | C4: TRUE | D4: FALSE | E4: FALSE | F4: FALSE | G4: FALSE | H4: FALSE | I4: TRUE | J4: TRUE | K4: FALSE | L4: FALSE | M4: TRUE | N4: FALSE | O4: TRUE
A5: Pitt bros | B5: Marquee | C5: TRUE | D5: FALSE | E5: FALSE | F5: FALSE | G5: FALSE | H5: FALSE | I5: TRUE | J5: TRUE | K5: FALSE | L5: FALSE | M5: TRUE | N5: FALSE | O5: TRUE
A6: Thindi | B6: Marquee | C6: TRUE | D6: FALSE | E6: FALSE | F6: FALSE | G6: FALSE | H6: FALSE | I6: TRUE | J6: TRUE | K6: FALSE | L6: FALSE | M6: TRUE | N6: FALSE | O6: TRUE
A7: Kiosk | B7: Nightclub Doors | C7: FALSE | D7: FALSE | E7: FALSE | F7: FALSE | G7: FALSE | H7: FALSE | I7: TRUE | J7: TRUE | K7: FALSE | L7: FALSE | M7: TRUE | N7: FALSE | O7: TRUE
A8: Coffee van | B8: Parade Ring | C8: TRUE | D8: FALSE | E8: FALSE | F8: FALSE | G8: FALSE | H8: FALSE | I8: TRUE | J8: TRUE | K8: FALSE | L8: FALSE | M8: TRUE | N8: FALSE | O8: TRUE
A9: Offbeat | B9: Parade Ring | C9: TRUE | D9: FALSE | E9: FALSE | F9: FALSE | G9: FALSE | H9: FALSE | I9: TRUE | J9: TRUE | K9: FALSE | L9: FALSE | M9: TRUE | N9: FALSE | O9: TRUE
A10: Caffe duomo | B10: Saddling Stalls | C10: FALSE | D10: FALSE | E10: FALSE | F10: FALSE | G10: FALSE | H10: FALSE | I10: TRUE | J10: TRUE | K10: FALSE | L10: FALSE | M10: TRUE | N10: FALSE | O10: TRUE
A11: Fried chicken | B11: Saddling Stalls | C11: TRUE | D11: FALSE | E11: FALSE | F11: FALSE | G11: FALSE | H11: FALSE | I11: TRUE | J11: TRUE | K11: FALSE | L11: FALSE | M11: TRUE | N11: FALSE | O11: TRUE
A12: Camile | B12: Saddling Stalls | C12: TRUE | D12: FALSE | E12: FALSE | F12: FALSE | G12: FALSE | H12: FALSE | I12: TRUE | J12: TRUE | K12: FALSE | L12: FALSE | M12: TRUE | N12: FALSE | O12: TRUE
A13: Loaded | B13: Saddling Stalls | C13: TRUE | D13: FALSE | E13: FALSE | F13: FALSE | G13: FALSE | H13: FALSE | I13: TRUE | J13: TRUE | K13: FALSE | L13: FALSE | M13: TRUE | N13: FALSE | O13: TRUE
A14: Bao Bun | B14: Saddling Stalls | C14: FALSE | D14: FALSE | E14: FALSE | F14: FALSE | G14: FALSE | H14: FALSE | I14: TRUE | J14: TRUE | K14: FALSE | L14: FALSE | M14: TRUE | N14: FALSE | O14: TRUE
A18: To Do List
C35: Position
A36: Stall/Unit Name | B36: Location | C36: 1 | D36: 2 | E36: 3 | F36: 4 | G36: 5 | H36: 6 | I36: 7
A37: Caffe Duomo | B37: Outside Gates | C37: Gwen | D37: Layla
A38: Toasted | B38: Marquee | C38: Nicola | D38: Mustafa | E38: Lorita
A39: Pitt bros | B39: Marquee | C39: Lauren | D39: Megan | F39: Abbie | G39: Berkay
A40: Thindi | B40: Marquee | C40: Megan | D40: Jodie | E40: Sophie
A41: Kiosk | B41: Nightclub Doors | C41: Kayla | D41: Layla
A42: Coffee van | B42: Parade Ring | C42: Janet | D42: Nicola | E42: Chloe
A43: Offbeat | B43: Parade Ring | C43: Tammy | D43: Renee | E43: Cuma
A44: Caffe duomo | B44: Saddling Stalls | C44: Emma p | D44: Nicole | E44: Vishnu
A45: Fried chicken | B45: Saddling Stalls | C45: Triona | D45: Paloma | E45: Alan
A46: Camile | B46: Saddling Stalls | C46: Sam | E46: Rachel | F46: Toni | G46: Amanda
A47: Loaded | B47: Saddling Stalls | C47: Ann | D47: Jess | E47: Leanna | F47: Michelle | G47: Ricky | H47: Ash | I47: Shane
A48: Bao Bun | B48: Saddling Stalls | C48: Marco | D48: Dave
A51: Confirmed | F51: Position
A52: Wesley | B52: KP | D52: Stall/Unit Name | E52: Location | F52: 1 | G52: 2 | H52: 3 | I52: 4 | J52: 5 | K52: 6 | L52: 7
A53: Lidiane | B53: Serving | D53: Caffe Duomo | E53: Outside Gates
A54: Alan | B54: KP | D54: Toasted | E54: Marquee | F54: Lorita | G54: Nicola | H54: Ava
A55: Felipe | B55: Serving | D55: Pitt bros | E55: Marquee | F55: Lauren | G55: Katelyn | H55: Megan | I55: Abbie
A56: Paloma | B56: Serving/Prep | D56: Thindi | E56: Marquee | F56: Dani | G56: Megan | H56: Emily
A57: Camila | B57: Serving/Prep | D57: Kiosk | E57: Nightclub Doors | F57: Kayla | G57: Layla
A58: Giovanna | B58: Serving | C58: ✅ | D58: Coffee van | E58: Parade Ring | F58: Janet | G58: Chloe | H58: Paloma
A59: Marco | B59: Chef/HACCP | C59: ✅ | D59: Offbeat | E59: Parade Ring | F59: Tammy | G59: Renee | H59: Kadie
A60: Eduardo | B60: KP/Prep | D60: Caffe duomo | E60: Saddling Stalls | F60: Emma | G60: Tracey | H60: Shane
D61: Fried chicken | E61: Saddling Stalls | F61: Alan | G61: Triona | H61: Marco
...

Sheet Google Engage
A1: Google Engage | I1: Stock & Orders
A2: Stall/Unit Name | B2: Location | C2: 🅿️ | D2: 🧽 | E2: ⚡️ | F2: 💻 | G2: 🧯 | H2: 👥 | I2: Sysco | J2: Camile | K2: ReadyChef | L2: BWG | M2: Pitt Bros | O2: Sandwiches | P2: Bretzel | Q2: Coffee Perfection
A3: Pizza Pasta | B3: Exit E | C3: FALSE | D3: FALSE | E3: FALSE | F3: FALSE | G3: FALSE | H3: FALSE | I3: FALSE | J3: FALSE | K3: FALSE | L3: FALSE | M3: FALSE | N3: FALSE | O3: FALSE | P3: FALSE | Q3: FALSE
A4: Pitt Bro's | C4: TRUE | D4: FALSE | E4: TRUE | F4: TRUE | G4: TRUE | H4: FALSE | I4: FALSE | J4: FALSE | K4: FALSE | L4: FALSE | M4: FALSE | N4: FALSE | O4: FALSE | P4: FALSE | Q4: FALSE
A5: Thindi | C5: TRUE | D5: FALSE | E5: FALSE | F5: TRUE | G5: TRUE | H5: FALSE | I5: FALSE | J5: FALSE | K5: FALSE | L5: FALSE | M5: FALSE | N5: FALSE | O5: FALSE | P5: FALSE | Q5: FALSE
A6: Toasted | C6: TRUE | D6: FALSE | E6: FALSE | F6: TRUE | G6: TRUE | H6: FALSE | I6: FALSE | J6: FALSE | K6: FALSE | L6: FALSE | M6: FALSE | N6: FALSE | O6: FALSE | P6: FALSE | Q6: FALSE
A7: Zambrero | C7: TRUE | D7: FALSE | E7: TRUE | F7: TRUE | G7: TRUE | H7: FALSE | I7: FALSE | J7: FALSE | K7: FALSE | L7: FALSE | M7: FALSE | N7: FALSE | O7: FALSE | P7: FALSE | Q7: FALSE
A8: Off Beat | C8: TRUE | D8: FALSE | E8: TRUE | F8: TRUE | G8: TRUE | H8: FALSE | I8: FALSE | J8: FALSE | K8: FALSE | L8: FALSE | M8: FALSE | N8: FALSE | O8: FALSE | P8: FALSE | Q8: FALSE
A9: Pizza Pasta | C9: TRUE | D9: FALSE | E9: TRUE | F9: TRUE | G9: TRUE | H9: FALSE | I9: FALSE | J9: FALSE | K9: FALSE | L9: FALSE | M9: FALSE | N9: FALSE | O9: FALSE | P9: FALSE | Q9: FALSE
A10: Cookie Bro | C10: TRUE | D10: FALSE | E10: TRUE | F10: TRUE | G10: FALSE | H10: FALSE | I10: FALSE | J10: FALSE | K10: FALSE | L10: FALSE | M10: FALSE | N10: FALSE | O10: FALSE | P10: FALSE | Q10: FALSE
A11: Popcorn | C11: TRUE | D11: FALSE | E11: FALSE | F11: TRUE | G11: FALSE | H11: FALSE | I11: FALSE | J11: FALSE | K11: FALSE | L11: FALSE | M11: FALSE | N11: FALSE | O11: FALSE | P11: FALSE | Q11: FALSE
A12: Candyfloss | C12: TRUE | D12: FALSE | E12: FALSE | F12: TRUE | G12: FALSE | H12: FALSE | I12: FALSE | J12: FALSE | K12: FALSE | L12: FALSE | M12: FALSE | N12: FALSE | O12: FALSE | P12: FALSE | Q12: FALSE
C13: FALSE | D13: FALSE | E13: FALSE | F13: FALSE | G13: FALSE | H13: FALSE | I13: FALSE | J13: FALSE | K13: FALSE | L13: FALSE | M13: FALSE | N13: FALSE | O13: FALSE | P13: FALSE | Q13: FALSE
C14: FALSE | D14: FALSE | E14: FALSE | F14: FALSE | G14: FALSE | H14: FALSE | I14: FALSE | J14: FALSE | K14: FALSE | L14: FALSE | M14: FALSE | N14: FALSE | O14: FALSE | P14: FALSE | Q14: FALSE
C15: FALSE | D15: FALSE | E15: FALSE | F15: FALSE | G15: FALSE | H15: FALSE | I15: FALSE | J15: FALSE | K15: FALSE | L15: FALSE | M15: FALSE | N15: FALSE | O15: FALSE | P15: FALSE | Q15: FALSE
C16: FALSE | D16: FALSE | E16: FALSE | F16: FALSE | G16: FALSE | H16: FALSE | I16: FALSE | J16: FALSE | K16: FALSE | L16: FALSE | M16: FALSE | N16: FALSE | O16: FALSE | P16: FALSE | Q16: FALSE
G21: Off Beat Donuts
A22: Zambrero | B22: LS NOTES | G22: EVENT MENU: (Donuts) | M22: Unit | N22: Number of staff | O22: Staff
A23: EVENT MENU: (Mexican) | M23: Pitt Bros | N23: 6 | O23: Lauren | P23: Ann | Q23: Mellisa | R23: Megan | S23: Katelyn | T23: Caoi
G24: Red Velvet (V) | K24: 2475 total servings | M24: Thindi | N24: 4 | O24: Megan | P24: Katelyn | Q24: Ava | R24: Sahill
A25: Burrito or Bowl | M25: Zambrero 8pm | N25: 8 | O25: Ryan | P25: Stacey | Q25: Lokesh | R25: Clara | S25: Sam | T25: Amanda
A26: Chicken | G26: Glazed (V) | M26: Pizza Pasta | N26: 6 | O26: Triona | P26: Lorrita | Q26: Tracey | R26: Mandy | S26: Marco
A27: Chilli “zin” carne (V, VG) | G27: Sprinkles (V) | M27: Toasted 9:45 | N27: 3 | O27: Janet | P27: Dean | Q27: Chaitanya
A28: WHITE RICE, PINTO BEANS, GUACAMOLE (with cos lettuce and lime), CHEESE, SOUR CREAM, JALAPENOS, SALSA (tomato, corn, onion) | G28: Unicorn (V) | M28: Cookie | N28: 3 | O28: Kadie | P28: Mariana | Q28: Chelsea
G29: Cookies & Cream (V) | M29: Popcorn | N29: 3 | O29: Karl | P29: Leah | Q29: Rachel
A30: Choice of Sauce | G30: Vegan Chocolate Cookie | M30: Candy floss | N30: 2 | O30: Dylan | P30: Kayleigh
A31: SECRET BBQ (Tamarind, cardamom and ginger) | G31: Vegan Caramel Speculoos | M31: Donut | N31: 3 | O31: Shannon | P31: Molly
A32: GARLIC (Roasted garlic, minced garlic, and creamy mayonnaise) | G32: Single donuts served in a bag - checking whether tray available | N32: =SUM(N23:N31) -> 38
A33: CHIPOTLE (Chipotle pepper, cayenne pepper, and lime) | G33: Can we please have a couple of vegan options | N33: Hot dog
A34: VERDE (Jalapeño peppers, mango, lemon, and coriander) | G34: Load in Friday 20th Feb Hall 1 | N34: Camile
N35: 42
A36: Side | G36: Cookiebro (Churros)
A37: Corn Tortillas with guacamole / salsa (V, VG) | G37: EVENT MENU: (Stuffed cookies)
K38: 1260 total servings
A39: Notes | G39: Oreo
A40: 7 Nov burrito was better filled than at horse show - please be consistent | G40: Crunchie
A41: Use smaller wrap to reduce burrito size | G41: Freddo | M41: Wages
A42: Tortilla chips come in big bag which will cause a lot of waste, so can we serve in a tray with some guacamole & salsa rather than whole bag | G42: Rollo | M42: Diego | N42: Braz | O42: Chelsea | P42: 100 | Q42: ✅
A43: Load in Friday 20th Feb Hall 1 | G43: Milky Bar | M43: Octa Sai | N43: Braz | O43: Mariana | P43: 105
G44: Lotus biscoff | M44: Wesley | N44: Braz | O44: Ahmed | P44: Braz
...

Sheet EP 25
A1: Electric Picnic | I1: Stock & Orders
A2: Stall/Unit Name | B2: Location | C2: 🅿️ | D2: 🧽 | E2: ⚡️ | F2: 💻 | G2: 🧯 | H2: 👥 | I2: Sysco | J2: Camile | K2: ReadyChef | L2: BWG | M2: Pitt Bros | N2: Sandwiches | O2: Bretzel | P2: Coffee Perfection | R2: Sleeping Arrangements
A3: Pizza Pasta | B3: Exit E | C3: FALSE | D3: FALSE | E3: FALSE | F3: FALSE | G3: FALSE | H3: FALSE | I3: FALSE | J3: FALSE | K3: FALSE | L3: FALSE | M3: FALSE | N3: FALSE | O3: FALSE | P3: FALSE | R3: Dads | S3: 4
A4: Pitt Bro's | B4: TBC | C4: FALSE | D4: FALSE | E4: FALSE | F4: FALSE | G4: FALSE | H4: FALSE | I4: TRUE | J4: TRUE | K4: FALSE | L4: TRUE | M4: TRUE | N4: FALSE | O4: TRUE | P4: TRUE | R4: Fiat | S4: 6
A5: Caffe Duomo | B5: TBC | C5: FALSE | D5: FALSE | E5: FALSE | F5: FALSE | G5: FALSE | H5: FALSE | I5: TRUE | J5: TRUE | K5: FALSE | L5: TRUE | M5: TRUE | N5: FALSE | O5: TRUE | P5: TRUE | R5: Transit | S5: 2
A6: Camile Thai | B6: TBC | C6: FALSE | D6: FALSE | E6: FALSE | F6: FALSE | G6: FALSE | H6: FALSE | I6: TRUE | J6: TRUE | K6: FALSE | L6: TRUE | M6: TRUE | N6: FALSE | O6: TRUE | P6: TRUE | R6: Showers | S6: 4
A7: Zambrero | B7: TBC | C7: FALSE | D7: FALSE | E7: FALSE | F7: FALSE | G7: FALSE | H7: FALSE | I7: TRUE | J7: TRUE | K7: FALSE | L7: TRUE | M7: TRUE | N7: FALSE | O7: TRUE | P7: TRUE | R7: VW | S7: 2
A8: Smash Burger 1 | B8: TBC | C8: FALSE | D8: FALSE | E8: FALSE | F8: FALSE | G8: FALSE | H8: FALSE | I8: TRUE | J8: TRUE | K8: FALSE | L8: TRUE | M8: TRUE | N8: FALSE | O8: TRUE | P8: TRUE | R8: Man Van | S8: 2
A9: Loaded Burger | B9: TBC | C9: FALSE | D9: FALSE | E9: FALSE | F9: FALSE | G9: FALSE | H9: FALSE | I9: TRUE | J9: TRUE | K9: FALSE | L9: TRUE | M9: TRUE | N9: FALSE | O9: TRUE | P9: TRUE | R9: Box Body | S9: 4
A10: Pizza/Pasta | B10: TBC | C10: FALSE | D10: FALSE | E10: FALSE | F10: FALSE | G10: FALSE | H10: FALSE | I10: FALSE | J10: TRUE | K10: FALSE | L10: TRUE | M10: TRUE | N10: FALSE | O10: TRUE | P10: TRUE | R10: Bedford | S10: 2
A11: Thindi | B11: TBC | C11: FALSE | D11: FALSE | E11: FALSE | F11: FALSE | G11: FALSE | H11: FALSE | I11: FALSE | J11: TRUE | K11: FALSE | L11: TRUE | M11: TRUE | N11: FALSE | O11: TRUE | P11: TRUE | R11: Total Beds | S11: =SUM(S3:S10) -> 26
A12: Ice Cream Vans | B12: TBC | C12: FALSE | D12: FALSE | E12: TRUE | F12: FALSE | G12: FALSE | H12: FALSE | I12: FALSE | J12: TRUE | K12: FALSE | L12: TRUE | M12: TRUE | N12: FALSE | O12: TRUE | P12: TRUE
A13: Ice Cream Unit 1 | B13: TBC | C13: FALSE | D13: FALSE | E13: FALSE | F13: FALSE | G13: FALSE | H13: FALSE | I13: FALSE | J13: TRUE | K13: FALSE | L13: TRUE | M13: TRUE | N13: FALSE | O13: TRUE | P13: TRUE
A14: Ice Cream Unit 2 | B14: TBC | C14: FALSE | D14: FALSE | E14: FALSE | F14: FALSE | G14: FALSE | H14: FALSE | I14: FALSE | J14: TRUE | K14: FALSE | L14: TRUE | M14: TRUE | N14: FALSE | O14: TRUE | P14: TRUE
A15: Ice Cream Unit 3 | B15: TBC | C15: FALSE | D15: FALSE | E15: FALSE | F15: FALSE | G15: FALSE | H15: FALSE | I15: FALSE | J15: TRUE | K15: FALSE | L15: TRUE | M15: TRUE | N15: FALSE | O15: TRUE | P15: TRUE
C16: FALSE | D16: FALSE | E16: FALSE | F16: FALSE | G16: FALSE | H16: FALSE | I16: FALSE | J16: TRUE | K16: FALSE | L16: TRUE | M16: TRUE | N16: FALSE | O16: TRUE | P16: TRUE | U16: Staff Names
U18: Staff Id | V18: Group Chat | W18: First Name | X18: Last Name | Y18: Phone Number | Z18: Email | AA18: Experience | AB18: Days Available
AB19: Thursday | AC19: Friday | AD19: Saturday | AE19: Sunday
A20: Unit ID | D20: Opening Hours | K20: Location | V20: FALSE | AB20: FALSE | AC20: FALSE | AD20: FALSE | AE20: FALSE
B21: # Staff | C21: Hrs | D21: # Staff | E21: Hrs | F21: # Staff | G21: Hrs | H21: # Staff | I21: Hrs | J21: # Staff | U21: 1 | V21: TRUE | W21: Thomas | X21: OBrien | Y21: 852402555 | Z21: thomas@obrieneventcatering.com | AB21: FALSE | AC21: FALSE | AD21: FALSE | AE21: FALSE
B22: Thursday | D22: Friday | F22: Saturday | H22: Sunday | J22: Monday | U22: =U21+1 -> 2 | V22: TRUE | W22: Patrick | X22: OBrien | Y22: 876192047 | AB22: FALSE | AC22: FALSE | AD22: FALSE | AE22: FALSE
A23: Pitt Bro's | B23: 2 | C23: 2 | D23: 5 | E23: 12 | F23: 6 | G23: 15 | H23: 6 | I23: 15 | K23: Main Arena | U23: =U22+1 -> 3 | V23: TRUE | W23: Kelly | X23: OBrien | Y23: 857106808 | AB23: FALSE | AC23: TRUE | AD23: TRUE | AE23: TRUE
A24: Caffe Duomo | B24: 2 | C24: 2 | D24: 5 | E24: 12 | F24: 6 | G24: 15 | H24: 6 | I24: 15 | K24: Main Arena | U24: =U23+1 -> 4 | V24: TRUE | W24: Flora | X24: OBrien | Y24: 872416613 | Z24: flora@obrieneventcatering.com | AB24: FALSE | AC24: FALSE | AD24: FALSE | AE24: FALSE
A25: Camile Thai | B25: 2 | C25: 2 | D25: 5 | E25: 12 | F25: 6 | G25: 15 | H25: 6 | I25: 15 | K25: Main Arena | U25: =U24+1 -> 5 | V25: TRUE | W25: Bridget | X25: Reid | AB25: FALSE | AC25: FALSE | AD25: FALSE | AE25: FALSE
A26: Zambrero | B26: 3 | C26: 4 | D26: 7 | E26: 12 | F26: 7 | G26: 15 | H26: 7 | I26: 15 | K26: Main Arena | U26: =U25+1 -> 6 | V26: TRUE | W26: Nicole | X26: Brady | AB26: FALSE | AC26: FALSE | AD26: FALSE | AE26: FALSE
A27: Smash Burger 1 | B27: 3 | C27: 2 | D27: 7 | E27: 12 | F27: 8 | G27: 15 | H27: 8 | I27: 15 | K27: Main Arena | U27: =U26+1 -> 7 | V27: TRUE | W27: Aaron | X27: Brady | AB27: FALSE | AC27: FALSE | AD27: FALSE | AE27: FALSE
A28: Loaded Burger | B28: 2 | C28: 2 | D28: 6 | E28: 12 | F28: 7 | G28: 15 | H28: 7 | I28: 15 | K28: Main Arena | U28: =U27+1 -> 8 | V28: TRUE | W28: Maisy | X28: Brady | AB28: FALSE | AC28: TRUE | AD28: TRUE | AE28: TRUE
A29: Pizza/Pasta | B29: 2 | C29: 2 | D29: 6 | E29: 12 | F29: 7 | G29: 15 | H29: 7 | I29: 15 | K29: Main Arena | U29: =U28+1 -> 9 | V29: TRUE | W29: Cian | X29: Ritchie | Y29: 877073894 | AA29: Ice Cream | AB29: FALSE | AC29: TRUE | AD29: TRUE | AE29: TRUE
A30: Thindi | B30: 2 | C30: 2 | D30: 6 | E30: 12 | F30: 7 | G30: 15 | H30: 7 | I30: 15 | K30: Main Arena | U30: =U29+1 -> 10 | V30: TRUE | W30: Cian | X30: Whelan | Y30: 877073894 | AA30: Ice Cream | AB30: FALSE | AC30: TRUE | AD30: TRUE | AE30: TRUE
A31: Ice Cream Vans | K31: Main Arena | U31: =U30+1 -> 11 | V31: TRUE | W31: Nicola | X31: Fennell | AB31: TRUE | AC31: TRUE | AD31: TRUE | AE31: TRUE
A32: Ice Cream Unit 1 | B32: 1 | C32: 1 | D32: 2 | E32: 12 | F32: 2 | G32: 15 | H32: 2 | I32: 15 | K32: Main Arena | U32: =U31+1 -> 12 | V32: TRUE | W32: Amanda | X32: Murray | AB32: TRUE | AC32: TRUE | AD32: TRUE | AE32: TRUE
A33: Ice Cream Unit 2 | B33: 1 | C33: 1 | D33: 2 | E33: 12 | F33: 2 | G33: 15 | H33: 2 | I33: 15 | K33: Main Arena | U33: =U32+1 -> 13 | V33: TRUE | W33: Donna | X33: ONeill | AB33: TRUE | AC33: TRUE | AD33: TRUE | AE33: TRUE
A34: Ice Cream Unit 3 | B34: 1 | C34: 1 | D34: 1 | E34: 12 | F34: 2 | G34: 15 | H34: 2 | I34: 15 | K34: Main Arena | U34: =U33+1 -> 14 | V34: TRUE | W34: Mandy | X34: Whelan | AB34: TRUE | AC34: TRUE | AD34: TRUE | AE34: TRUE
B35: 1 | C35: 1 | D35: 1 | E35: 12 | F35: 1 | G35: 15 | H35: 1 | I35: 15 | K35: Main Arena | U35: =U34+1 -> 15 | V35: TRUE | W35: Brooke | X35: ONeill | AB35: TRUE | AC35: TRUE | AD35: TRUE | AE35: TRUE
B36: 1 | C36: 1 | D36: 1 | E36: 12 | F36: 2 | G36: 15 | H36: 2 | I36: 15 | K36: Main Arena | U36: =U35+1 -> 16 | V36: TRUE | W36: Emily | X36: Whelan | AB36: TRUE | AC36: TRUE | AD36: TRUE | AE36: TRUE
A37: Stock Boys | B37: 4 | C37: 10 | D37: 5 | E37: 12 | F37: 5 | G37: 12 | H37: 5 | I37: 12 | K37: Main Arena | U37: =U36+1 -> 17 | V37: TRUE | W37: Karla | X37: Brady | AB37: FALSE | AC37: TRUE | AD37: TRUE | AE37: TRUE
U38: =U37+1 -> 18 | V38: TRUE | W38: Dylan | X38: ODriscoll | Y38: 857645690 | Z38: dylanodriscoll00@gmail.com | AB38: FALSE | AC38: TRUE | AD38: TRUE | AE38: TRUE
U39: =U38+1 -> 19 | V39: TRUE | W39: Darren | X39: ODriscoll | Y39: 858159925 | Z39: darrenodriscoll2019@gmail.com | AA39: Food | AB39: FALSE | AC39: TRUE | AD39: TRUE | AE39: TRUE
U40: =U39+1 -> 20 | V40: TRUE | W40: Jade | X40: Malone | Y40: 852022709 | Z40: jademalone1993@live.com | AA40: Food | AB40: FALSE | AC40: TRUE | AD40: TRUE | AE40: TRUE
A41: Totals Needed | B41: =SUM(B23:B40) -> 27 | C41: =SUM(C23:C40) -> 33 | D41: =SUM(D23:D40) -> 59 | E41: =SUM(E23:E40) -> 168 | F41: =SUM(F23:F40) -> 68 | G41: =SUM(G23:G40) -> 207 | H41: =SUM(H23:H40) -> 68 | I41: =SUM(I23:I40) -> 207 | J41: =SUM(J23:J40) -> 0 | U41: =U40+1 -> 21 | V41: TRUE | W41: Louise | X41: Malone | Y41: 857302419 | Z41: louisemalone21@gmail.com | AA41: Food | AB41: FALSE | AC41: FALSE | AD41: TRUE | AE41: TRUE
...

Sheet Iveagh Gardens Takings 
A1: Date | B1: Cash | C1: Card
A2: 45841 | B2: 150 | C2: 1601
A3: 45842 | B3: 114 | C3: 896
A4: 45844 | B4: 218 | C4: 1104
A5: 45849 | B5: 210 | C5: 1738
A6: 45850 | B6: 300 | C6: 1951
A7: 45851 | B7: 435 | C7: 1951
A8: 45855 | B8: 395 | C8: 2547
A9: 45856 | B9: 222 | C9: 1596
A10: 45857 | B10: 250 | C10: 1078
A11: 45858 | B11: 465 | C11: 2130
A12: Total | B12: =SUM(B2:B11) -> 2759 | C12: =SUM(C2:C11) -> 16592
A13: 45862 | B13: 60 | C13: 1478.5
A14: 45863 | B14: 60.5 | C14: 2037
A15: 45864 | B15: 330 | C15: 2393
A16: 45865 | B16: 621 | C16: 1200.5

Sheet Staff & Trailers
A1: Name | B1: Trailers | C1: Trailers
A2: Samantha
A3: Lauren
A4: Stacey | B4: Camile pitt bros Zamb Thindi chip | C4: Pizza
A5: Ava | B5: "
A6: Dylan | B6: Ice cream pizza Camile chip coffee
A7: Dani | B7: Pizza camile Thindi chip ice cream
A8: Ann Marie | B8: Chip Pitt bros Zamb pizza
A9: Amanda | B9: " & camile
A10: Megan | B10: Camile Thindi pizza Pitt bros chip
A11: Shannon | B11: Toasty coffee ice cream pizza Camile chip
A12: Katelyn | B12: Chip ice cream Pitt bros pizza
A13: Nicola | B13: Coffee chip
A14: Lisa | B14: Toasty coffee chip
A15: Laura | B15: Toasty ice cream coffee chip
A16: Janet | B16: Toasty coffee
... A53: Taylor | B53: Cook
A54: Brophy
A55: Sean (Taylor) | B55: Chip
A56: Charlie Nolan | B56: Ice cream
A57: Caitlin Nolan | B57: Ice cream coffee
A58: Hilary | B58: Coffee
A59: Kyle | B59: Chip
A60: Lisa (viv) | B60: Coffee
A61: Sean (Nicola) | B61: Chip
A62: Aidan (Nicola) | B62: Chip
A63: Katie (triona) | B63: Chip pit bros
A64: Casandra (triona) | B64: Chip
A65: Becky (triona) | B65: Coffee
A66: Jess (Lorraine) | B66: Chip Zamb
... A71: Michelle | B71: Chip coffee ice cream

Sheet Zach Bryan
A1: Zach Bryan | I1: Stock & Orders
A2: Stall/Unit Name | B2: Location | C2: 🅿️ | D2: 🧽 | E2: ⚡️ | F2: 💻 | G2: 🧯 | H2: 👥 | I2: Sysco | J2: Camile | L2: ReadyChef | M2: BWG | N2: Pitt Bros | O2: Delimeats | P2: Bretzel
A3: Pizza Pasta | B3: Exit E | C3: FALSE | D3: FALSE | E3: FALSE | F3: FALSE | G3: FALSE | H3: FALSE | I3: FALSE | J3: FALSE | K3: FALSE | L3: FALSE | M3: FALSE | N3: FALSE | O3: FALSE | P3: FALSE
A4: Loaded | B4: Toilets | C4: TRUE | D4: TRUE | E4: TRUE | F4: FALSE | G4: FALSE | H4: FALSE | I4: FALSE | J4: TRUE | K4: FALSE | L4: FALSE | M4: TRUE | N4: TRUE | O4: TRUE | P4: FALSE
A5: Smash | B5: Toilets | C5: TRUE | D5: TRUE | E5: TRUE | F5: FALSE | G5: FALSE | H5: FALSE | I5: FALSE | J5: TRUE | K5: FALSE | L5: FALSE | M5: TRUE | N5: TRUE | O5: TRUE | P5: FALSE
A6: Camile | B6: Side Stage | C6: TRUE | D6: TRUE | E6: TRUE | F6: FALSE | G6: FALSE | H6: FALSE | I6: FALSE | J6: TRUE | K6: FALSE | L6: FALSE | M6: TRUE | N6: TRUE | O6: TRUE | P6: FALSE
A7: Pitt Bros | B7: Toilets (Back Line) | C7: TRUE | D7: TRUE | E7: TRUE | F7: FALSE | G7: FALSE | H7: FALSE | I7: FALSE | J7: TRUE | K7: FALSE | L7: FALSE | M7: TRUE | N7: TRUE | O7: TRUE | P7: FALSE
A8: Thindi | B8: Toilets (Back Line) | C8: TRUE | D8: TRUE | E8: TRUE | F8: FALSE | G8: FALSE | H8: FALSE | I8: FALSE | J8: TRUE | K8: FALSE | L8: FALSE | M8: TRUE | N8: TRUE | O8: TRUE | P8: FALSE
A9: Zambrero | B9: Back Of Main Arena (Spine) | C9: TRUE | D9: TRUE | E9: TRUE | F9: FALSE | G9: FALSE | H9: FALSE | I9: FALSE | J9: TRUE | K9: FALSE | L9: FALSE | M9: TRUE | N9: TRUE | O9: TRUE | P9: FALSE
A10: Off Beat | B10: Back Of Main Arena (Spine) | C10: TRUE | D10: TRUE | E10: TRUE | F10: FALSE | G10: FALSE | H10: FALSE | I10: FALSE | J10: TRUE | K10: FALSE | L10: FALSE | M10: TRUE | N10: TRUE | O10: TRUE | P10: FALSE
A11: Smash | B11: Toilets (Back Line) | C11: TRUE | D11: TRUE | E11: TRUE | F11: FALSE | G11: FALSE | H11: FALSE | I11: FALSE | J11: TRUE | K11: FALSE | L11: FALSE | M11: TRUE | N11: TRUE | O11: TRUE | P11: FALSE
A12: Pizza/Pasta | B12: Toilets (Back Line) | C12: TRUE | D12: TRUE | E12: TRUE | F12: FALSE | G12: FALSE | H12: FALSE | I12: FALSE | J12: TRUE | K12: FALSE | L12: FALSE | M12: TRUE | N12: TRUE | O12: TRUE | P12: FALSE
A13: Kiosk | B13: Back Of Main Arena (Spine) | C13: TRUE | D13: TRUE | E13: TRUE | F13: FALSE | G13: FALSE | H13: FALSE | I13: FALSE | J13: TRUE | K13: FALSE | L13: FALSE | M13: TRUE | N13: TRUE | O13: TRUE | P13: FALSE
A14: Coffee | B14: Family Area | C14: FALSE | D14: FALSE | E14: TRUE | F14: FALSE | G14: FALSE | H14: FALSE | I14: FALSE | J14: TRUE | K14: FALSE | L14: FALSE | M14: TRUE | N14: TRUE | O14: TRUE | P14: FALSE
... A16: Ice Cream | B16: N/A | C16: FALSE | D16: FALSE | E16: FALSE | F16: FALSE | G16: FALSE | H16: FALSE | I16: FALSE | J16: TRUE | K16: FALSE | L16: FALSE | M16: TRUE | N16: TRUE | O16: TRUE | P16: FALSE
A20: Unit ID | B20: Opening Hours | I20: Location | L20: Takings
B21: # Staff | C21: Hrs | D21: # Staff | E21: Hrs | F21: # Staff | G21: Hrs | H21: # Staff | L21: Stall/Unit Name | M21: Location | P21: Day | S21: Total
B22: Friday | D22: Saturday | F22: Sunday | H22: Monday | L22: Pizza Pasta | M22: Exit E | P22: Friday | Q22: Saturday | R22: Sunday
A23: Loaded | B23: 8 | C23: 9 | D23: 8 | E23: 9 | F23: 8 | G23: 9 | I23: Toilets | L23: Loaded | M23: Toilets | P23: 6438 | Q23: 7258.5 | R23: 6871.05 | S23: =SUM(P23:R23) -> 20567.55
A24: Smash | B24: 8 | C24: 9 | D24: 8 | E24: 9 | F24: 8 | G24: 9 | I24: Toilets | L24: Smash | M24: Toilets | P24: 4497 | Q24: 4895.3 | R24: 5993.65 | S24: =SUM(P24:R24) -> 15385.95
A25: Camile | B25: 8 | C25: 9 | D25: 8 | E25: 9 | F25: 8 | G25: 9 | I25: Side Stage | L25: Camile | M25: Side Stage | P25: 11955 | Q25: 15466.25 | R25: 13656.25 | S25: =SUM(P25:R25) -> 41077.5
A26: Pitt Bros | B26: 5 | C26: 9 | D26: 5 | E26: 9 | F26: 5 | G26: 9 | I26: Toilets (Back Line) | L26: Pitt Bros | M26: Toilets (Back Line) | P26: 5373.5 | Q26: 5612.45 | R26: 6929.3 | S26: =SUM(P26:R26) -> 17915.25
A27: Thindi | B27: 4 | C27: 9 | D27: 4 | E27: 9 | F27: 4 | G27: 9 | I27: Toilets (Back Line) | L27: Thindi | M27: Toilets (Back Line) | P27: 1644.31 | Q27: 2033.23 | R27: 1256.93 | S27: =SUM(P27:R27) -> 4934.47
A28: Zambrero | B28: 8 | C28: 9 | D28: 8 | E28: 9 | F28: 8 | G28: 9 | I28: Back Of Main Arena (Spine) | L28: Zambrero | M28: Back Of Main Arena (Spine) | P28: 8938 | Q28: 11569.3 | R28: 11057.65 | S28: =SUM(P28:R28) -> 31564.95
A29: Off Beat | B29: 3 | C29: 9 | D29: 3 | E29: 9 | F29: 3 | G29: 9 | I29: Back Of Main Arena (Spine) | L29: Off Beat | M29: Back Of Main Arena (Spine) | P29: 4448.75 | Q29: 5884.61 | R29: 4940.3 | S29: =SUM(P29:R29) -> 15273.66
A30: Smash | B30: 8 | C30: 9 | D30: 8 | E30: 9 | F30: 8 | G30: 9 | I30: Toilets (Back Line) | L30: Smash | M30: Toilets (Back Line) | P30: 7930 | Q30: 10858.3 | R30: 11961.6 | S30: =SUM(P30:R30) -> 30749.9
A31: Pizza/Pasta | B31: 5 | C31: 9 | D31: 5 | E31: 9 | F31: 5 | G31: 9 | I31: Toilets (Back Line) | L31: Pizza/Pasta | M31: Toilets (Back Line) | P31: 4727 | Q31: 7852.6 | R31: 6081.15 | S31: =SUM(P31:R31) -> 18660.75
A32: Kiosk | B32: 3 | C32: 9 | D32: 3 | E32: 9 | F32: 3 | G32: 9 | I32: Back Of Main Arena (Spine) | L32: Kiosk | M32: Back Of Main Arena (Spine) | P32: 9258.25 | Q32: 10832.5 | R32: 8694.5 | S32: =SUM(P32:R32) -> 28785.25
A33: Coffee | B33: 3 | C33: 9 | D33: 3 | E33: 9 | F33: 3 | G33: 9 | I33: Family Area | L33: Coffee | M33: Family Area | P33: 2022.8 | Q33: 3619.3 | R33: 2871.45 | S33: =SUM(P33:R33) -> 8513.55
A34: Coffee | B34: 2 | C34: 9 | D34: 2 | E34: 9 | F34: 2 | G34: 9 | I34: Toilets (Back Line) | L34: Coffee | M34: Toilets (Back Line) | P34: 3026.9 | Q34: 3843.55 | R34: 4243.15 | S34: =SUM(P34:R34) -> 11113.6
A35: Ice Cream | B35: 2 | C35: 9 | D35: 2 | E35: 9 | F35: 2 | G35: 9 | I35: N/A | L35: Ice Cream | M35: Middle Arena Bar | P35: 5385 | Q35: 4060.6 | R35: 2374.1 | S35: =SUM(P35:R35) -> 11819.7
A36: Ice Cream | B36: 2 | C36: 9 | D36: 2 | E36: 9 | F36: 2 | G36: 9 | I36: N/A | L36: Ice Cream | M36: Early Entry/Gate 4 | P36: 4000 | Q36: 3289 | R36: 1710 | S36: =SUM(P36, Q36, R36) -> 8999
L37: Ice Cream | M37: Chesterfield Av @ Aras Gates | P37: (Sat/Sun Only) | Q37: 3755 | R37: 2690
O38: Total | P38: =SUM(P23:P37) -> 79644.51 | Q38: =SUM(Q23:Q37) -> 100830.49 | R38: =SUM(R23:R35) -> 86931.08 | S38: =SUM(P38, Q38, R38) -> 267406.08
A39: Stock Boys | B39: 4 | C39: 9 | D39: 4 | E39: 9 | F39: 4 | G39: 9 | I39: Main Arena | O39: Commission | P39: =P38*20% -> 15928.902 | Q39: =Q38*20% -> 20166.098 | R39: =R38*20% -> 17386.216 | S39: =SUM(P39, Q39, R39) -> 53481.216
A40: Total | B40: =SUM(B23:B39) -> 73 | O40: Expected Payout | P40: =P38-P39 -> 63715.608 | Q40: =Q38-Q39 -> 80664.392 | R40: =R38-R39 -> 69544.864 | S40: =SUM(P40, Q40, R40) -> 213924.86
O41: Actual Payout
O42: WIFI/Power/Card
A44: Staff Names
A46: Staff Id | B46: Group Chat | C46: First Name | D46: Last Name | E46: Phone Number | F46: Email | G46: Source | H46: Days Available | K46: Wages
...

Sheet Kaleidoscope 25
B3: Kaleidoscope | J3: Stock & Orders
B4: Stall/Unit Name | C4: Location | D4: 🅿️ | E4: 🧽 | F4: ⚡️ | G4: 💻 | H4: 🧯 | I4: 👥 | J4: Sysco | K4: Camile | M4: ReadyChef | N4: BWG | O4: Pitt Bros | P4: Delimeats | Q4: Off Beat
B5: Pizza Pasta | C5: Exit E | D5: FALSE | E5: FALSE | F5: FALSE | G5: FALSE | H5: FALSE | I5: FALSE | J5: FALSE | K5: FALSE | L5: FALSE | M5: FALSE | N5: FALSE | O5: FALSE | P5: FALSE | Q5: FALSE
B6: Loaded | D6: TRUE | E6: FALSE | F6: FALSE | G6: FALSE | H6: FALSE | I6: FALSE | J6: FALSE | K6: TRUE | L6: FALSE | M6: FALSE | N6: TRUE | O6: FALSE | P6: TRUE | Q6: TRUE
B7: Camille | D7: TRUE | E7: FALSE | F7: FALSE | G7: FALSE | H7: FALSE | I7: FALSE | J7: FALSE | K7: TRUE | L7: FALSE | M7: FALSE | N7: TRUE | O7: FALSE | P7: TRUE | Q7: TRUE
B8: Pizza Pasta | D8: TRUE | E8: FALSE | F8: FALSE | G8: TRUE | H8: FALSE | I8: FALSE | J8: FALSE | K8: TRUE | L8: FALSE | M8: FALSE | N8: TRUE | O8: FALSE | P8: TRUE | Q8: TRUE
B9: Toasted | D9: TRUE | E9: FALSE | F9: FALSE | G9: FALSE | H9: FALSE | I9: FALSE | J9: FALSE | K9: TRUE | L9: FALSE | M9: FALSE | N9: TRUE | O9: FALSE | P9: TRUE | Q9: TRUE
B10: Off Beat | D10: TRUE | E10: FALSE | F10: FALSE | G10: FALSE | H10: FALSE | I10: FALSE | J10: FALSE | K10: TRUE | L10: FALSE | M10: FALSE | N10: TRUE | O10: FALSE | P10: TRUE | Q10: TRUE
B11: Zambrero | D11: TRUE | E11: FALSE | F11: FALSE | G11: FALSE | H11: FALSE | I11: FALSE | J11: FALSE | K11: TRUE | L11: FALSE | M11: FALSE | N11: TRUE | O11: FALSE | P11: TRUE | Q11: TRUE
B12: Duomo - relocated | D12: TRUE | E12: FALSE | F12: FALSE | G12: FALSE | H12: FALSE | I12: FALSE | J12: FALSE | K12: TRUE | L12: FALSE | M12: FALSE | N12: TRUE | O12: FALSE | P12: TRUE | Q12: TRUE
B13: Ice Cream | D13: TRUE | E13: FALSE | F13: FALSE | G13: FALSE | H13: FALSE | I13: FALSE | J13: FALSE | K13: TRUE | L13: FALSE | M13: FALSE | N13: TRUE | O13: FALSE | P13: TRUE | Q13: TRUE
B14: Ice Cream | D14: TRUE | E14: FALSE | F14: FALSE | G14: FALSE | H14: FALSE | I14: FALSE | J14: FALSE | K14: TRUE | L14: FALSE | M14: FALSE | N14: TRUE | O14: FALSE | P14: TRUE | Q14: TRUE
B15: Ice Cream | D15: TRUE | E15: FALSE | F15: FALSE | G15: FALSE | H15: FALSE | I15: FALSE | J15: FALSE | K15: TRUE | L15: FALSE | M15: FALSE | N15: TRUE | O15: FALSE | P15: TRUE | Q15: TRUE
D16: FALSE | E16: FALSE | F16: FALSE | G16: FALSE | H16: FALSE | I16: FALSE | J16: FALSE | K16: TRUE | L16: FALSE | M16: FALSE | N16: TRUE | O16: FALSE | P16: TRUE | Q16: TRUE
D17: FALSE | E17: FALSE | F17: FALSE | G17: FALSE | H17: FALSE | I17: FALSE | J17: FALSE | K17: TRUE | L17: FALSE | M17: FALSE | N17: TRUE | O17: FALSE | P17: TRUE | Q17: TRUE
D18: FALSE | E18: FALSE | F18: FALSE | G18: FALSE | H18: FALSE | I18: FALSE | J18: FALSE | K18: TRUE | L18: FALSE | M18: FALSE | N18: TRUE | O18: FALSE | P18: TRUE | Q18: TRUE
B22: Unit ID | C22: Opening Hours | J22: Location | M22: Takings
C23: # Staff | D23: Hrs | E23: # Staff | F23: Hrs | G23: # Staff | H23: Hrs | I23: # Staff | M23: Stall/Unit Name | N23: Location | Q23: Day | T23: Total
C24: Friday | E24: Saturday | G24: Sunday | I24: Monday | M24: Pizza Pasta | N24: Exit E | Q24: Friday | R24: Saturday | S24: Sunday
B25: Loaded | C25: 5 | D25: 9 | E25: 8 | F25: 9 | G25: 8 | H25: 9 | M25: Loaded | T25: =SUM(Q25:S25) -> 0
B26: Camille | C26: 5 | D26: 9 | E26: 8 | F26: 9 | G26: 8 | H26: 9 | M26: Camille | T26: =SUM(Q26:S26) -> 0
B27: Pizza Pasta | C27: 4 | D27: 9 | E27: 5 | F27: 9 | G27: 5 | H27: 9 | M27: Pizza Pasta | T27: =SUM(Q27:S27) -> 0
B28: Toasted | C28: 3 | D28: 9 | E28: 4 | F28: 9 | G28: 4 | H28: 9 | M28: Toasted | T28: =SUM(Q28:S28) -> 0
B29: Off Beat | C29: 3 | D29: 9 | E29: 4 | F29: 9 | G29: 4 | H29: 9 | M29: Off Beat | T29: =SUM(Q29:S29) -> 0
B30: Zambrero | C30: 6 | D30: 9 | E30: 8 | F30: 9 | G30: 8 | H30: 9 | M30: Zambrero | T30: =SUM(Q30:S30) -> 0
B31: Duomo - relocated | C31: 2 | D31: 9 | E31: 3 | F31: 9 | G31: 3 | H31: 9 | M31: Duomo - relocated | T31: =SUM(Q31:S31) -> 0
B32: Ice Cream | C32: 1 | D32: 9 | E32: 2 | F32: 9 | G32: 2 | H32: 9 | M32: Ice Cream | T32: =SUM(Q32:S32) -> 0
B33: Ice Cream | C33: 1 | D33: 9 | E33: 2 | F33: 9 | G33: 2 | H33: 9 | M33: Ice Cream | T33: =SUM(Q33:S33) -> 0
B34: Ice Cream | C34: 1 | D34: 9 | E34: 1 | F34: 9 | G34: 1 | H34: 9 | M34: Ice Cream | T34: =SUM(Q34:S34) -> 0
T35: =SUM(Q35:S35) -> 0
T36: =SUM(Q36:S36) -> 0
T37: =SUM(Q37:S37) -> 0
T38: =SUM(Q38, R38, S38) -> 0
P40: Total | Q40: =SUM(Q25:Q39) -> 0 | R40: =SUM(R25:R39) -> 0 | S40: =SUM(S25:S37) -> 0 | T40: =SUM(Q40, R40, S40) -> 0
B41: Stock Boys | C41: 2 | D41: 9 | E41: 3 | F41: 9 | G41: 3 | H41: 9 | J41: Main Arena | P41: Commission | Q41: =Q40*20% -> 0 | R41: =R40*20% -> 0 | S41: =S40*20% -> 0 | T41: =SUM(Q41, R41, S41) -> 0
B42: Total | C42: =SUM(C25:C41) -> 33 | D42: =SUM(D25:D41) -> 99 | E42: =SUM(E25:E41) -> 48 | F42: =SUM(F25:F41) -> 99 | G42: =SUM(G25:G41) -> 48 | H42: =SUM(H25:H41) -> 99 | I42: =SUM(I25:I41) -> 0 | J42: =SUM(J25:J41) -> 0 | K42: =SUM(K25:K41) -> 0 | P42: Expected Payout | Q42: =Q40-Q41 -> 0 | R42: =R40-R41 -> 0 | S42: =S40-S41 -> 0 | T42: =SUM(Q42, R42, S42) -> 0
P43: Actual Payout
P44: WIFI/Power/Card
B46: Staff Names
B48: Staff Id | C48: Group Chat | D48: First Name | E48: Last Name | F48: Phone Number | G48: Email | H48: Source | I48: Days Available | L48: Wages
...

Sheet LATM
A1: Live at the Marquee
A2: Stall/Unit Name | C2: 🅿️ | D2: 🧽 | E2: ⚡️ | F2: 🌡️ | G2: 💻
A3: Pizza Pasta | C3: FALSE | D3: FALSE | E3: FALSE | F3: FALSE | G3: FALSE | H3: FALSE
A4: Smash Burger | C4: FALSE | D4: FALSE | E4: FALSE | F4: FALSE | G4: FALSE | H4: FALSE
A5: Pitt Bros BBQ | C5: FALSE | D5: FALSE | E5: FALSE | F5: FALSE | G5: FALSE | H5: FALSE
A6: Franks Hot Dog | C6: FALSE | D6: FALSE | E6: FALSE | F6: FALSE | G6: FALSE | H6: FALSE
A7: Angelo's Pizza | C7: FALSE | D7: FALSE | E7: FALSE | F7: FALSE | G7: FALSE | H7: FALSE
A8: Kiosk | C8: FALSE | D8: FALSE | E8: FALSE | F8: FALSE | G8: FALSE | H8: FALSE
A9: Caffe Duomo | C9: FALSE | D9: FALSE | E9: FALSE | F9: FALSE | G9: FALSE | H9: FALSE
A10: Coca Cola Can | C10: FALSE | D10: FALSE | E10: FALSE | F10: FALSE | G10: FALSE | H10: FALSE
A11: Ice Cream Van | C11: FALSE | D11: FALSE | E11: FALSE | F11: FALSE | G11: FALSE | H11: FALSE
A14: Takings | C14: 45833 | E14: 45834 | G14: 45835 | I14: 45836 | K14: 45837 | M14: 45839 | O14: 45840 | Q14: 45841 | S14: 45842 | U14: 45843 | W14: 45845 | Y14: 45846 | AA14: 45847 | AC14: 45848 | AE14: 45849 | AG14: 45850 | AI14: 45851 | AK14: 45854 | AM14: 45855 | AO14: 45856 | AQ14: 45857 | AS14: 45858 | AU14: 45860 | AW14: 45861 | AY14: 45862 | BA14: 45863 | BC14: 45864 | BE14: 45865
C15: Picture This -Sold Out | E15: Picture This -Extra Date Added | G15: The Coronas | I15: Christy Moore -Sold Out | K15: Dara O‘Briain | M15: Joe Bonamassa Plays Rory Gallagher -Sold Out | O15: Joe Bonamassa Plays Rory Gallagher -Sold Out | Q15: Joe Bonamassa Plays Rory Gallagher -Extra Date | S15: Tommy Tiernan | U15: Tommy Tiernan - Sold Out | W15: Roy Keane and Roddy Doyle - Sold Out | Y15: Roy Keane and Roddy Doyle - Sold Out | AA15: Roy Keane and Roddy Doyle - Sold Out | AC15: The Waterboys | AE15: Chris Kent | AG15: Dec Pierce | AI15: Olly Murs | AK15: Kingfishr - Sold Out | AM15: Amble - Sold Out | AO15: The Mary Wallopers | AQ15: Cian Ducrot - Sold Out | AS15: Cian Ducrot | AU15: D-Block Europe | AW15: D-Block Europe - Sold Out | AY15: Kingfishr - Sold Out | BA15: Michael McIntyre - Sold Out | BC15: Michael McIntyre - Sold Out | BE15: Michael McIntyre - Sold Out
C16: Cash | D16: Card | E16: Cash | F16: Card | G16: Cash | H16: Card | I16: Cash | J16: Card | K16: Cash | L16: Card | M16: Cash | N16: Card | O16: Cash | P16: Card | Q16: Cash | R16: Card | S16: Cash | T16: Card | U16: Cash | V16: Card | W16: Cash | X16: Card | Y16: Cash | Z16: Card | AA16: Cash | AB16: Card | AC16: Cash | AD16: Card | AE16: Cash | AF16: Card | AG16: Cash | AH16: Card | AI16: Cash | AJ16: Card | AK16: Cash | AL16: Card | AM16: Cash | AN16: Card | AO16: Cash | AP16: Card | AQ16: Cash | AR16: Card | AS16: Cash | AT16: Card | AU16: Cash | AV16: Card | AW16: Cash | AX16: Card | AY16: Cash | AZ16: Card | BA16: Cash | BB16: Card | BC16: Cash | BD16: Card | BE16: Cash | BF16: Card | BG16: Cash | BH16: Card
A17: Smash Burger | C17: 360 | D17: 2980 | E17: 490 | F17: 2856 | BG17: =SUM(C17, E17, G17, I17, K17, M17, O17, Q17, S17, U17, W17, Y17, AA17, AC17, AE17, AG17, AI17, AK17, AM17, AO17, AQ17, AS17, AU17, AW17, AY17, BA17, BC17, BE17) -> 850 | BH17: =SUM(D17, F17, H17, J17, L17, N17, P17, R17, T17, V17, X17, Z17, AB17, AD17, AF17, AH17, AJ17, AL17, AN17, AP17, AR17, AT17, AV17, AX17, AZ17, BB17, BD17, BF17) -> 5836
A18: Pitt Bros BBQ | C18: 790 | D18: 531 | E18: 510 | F18: 962 | BG18: =SUM(C18, E18, G18, I18, K18, M18, O18, Q18, S18, U18, W18, Y18, AA18, AC18, AE18, AG18, AI18, AK18, AM18, AO18, AQ18, AS18, AU18, AW18, AY18, BA18, BC18, BE18) -> 1300 | BH18: =SUM(D18, F18, H18, J18, L18, N18, P18, R18, T18, V18, X18, Z18, AB18, AD18, AF18, AH18, AJ18, AL18, AN18, AP18, AR18, AT18, AV18, AX18, AZ18, BB18, BD18, BF18) -> 1493
A19: Franks Hot Dog | C19: 300 | D19: 1564 | E19: 390 | F19: 1600 | BG19: =SUM(C19, E19, G19, I19, K19, M19, O19, Q19, S19, U19, W19, Y19, AA19, AC19, AE19, AG19, AI19, AK19, AM19, AO19, AQ19, AS19, AU19, AW19, AY19, BA19, BC19, BE19) -> 690 | BH19: =SUM(D19, F19, H19, J19, L19, N19, P19, R19, T19, V19, X19, Z19, AB19, AD19, AF19, AH19, AJ19, AL19, AN19, AP19, AR19, AT19, AV19, AX19, AZ19, BB19, BD19, BF19) -> 3164
A20: Angelo's Pizza | C20: 250 | D20: 1080 | E20: 190 | F20: 1000 | BG20: =SUM(C20, E20, G20, I20, K20, M20, O20, Q20, S20, U20, W20, Y20, AA20, AC20, AE20, AG20, AI20, AK20, AM20, AO20, AQ20, AS20, AU20, AW20, AY20, BA20, BC20, BE20) -> 440 | BH20: =SUM(D20, F20, H20, J20, L20, N20, P20, R20, T20, V20, X20, Z20, AB20, AD20, AF20, AH20, AJ20, AL20, AN20, AP20, AR20, AT20, AV20, AX20, AZ20, BB20, BD20, BF20) -> 2080
A21: Kiosk | C21: 415 | D21: 2864 | E21: 580 | F21: 1609 | BG21: =SUM(C21, E21, G21, I21, K21, M21, O21, Q21, S21, U21, W21, Y21, AA21, AC21, AE21, AG21, AI21, AK21, AM21, AO21, AQ21, AS21, AU21, AW21, AY21, BA21, BC21, BE21) -> 995 | BH21: =SUM(D21, F21, H21, J21, L21, N21, P21, R21, T21, V21, X21, Z21, AB21, AD21, AF21, AH21, AJ21, AL21, AN21, AP21, AR21, AT21, AV21, AX21, AZ21, BB21, BD21, BF21) -> 4473
A22: Caffe Duomo | C22: 650 | D22: 420 | E22: 120 | F22: 760 | BG22: =SUM(C22, E22, G22, I22, K22, M22, O22, Q22, S22, U22, W22, Y22, AA22, AC22, AE22, AG22, AI22, AK22, AM22, AO22, AQ22, AS22, AU22, AW22, AY22, BA22, BC22, BE22) -> 770 | BH22: =SUM(D22, F22, H22, J22, L22, N22, P22, R22, T22, V22, X22, Z22, AB22, AD22, AF22, AH22, AJ22, AL22, AN22, AP22, AR22, AT22, AV22, AX22, AZ22, BB22, BD22, BF22) -> 1180
A23: Coca Cola Can | BG23: =SUM(C23, E23, G23, I23, K23, M23, O23, Q23, S23, U23, W23, Y23, AA23, AC23, AE23, AG23, AI23, AK23, AM23, AO23, AQ23, AS23, AU23, AW23, AY23, BA23, BC23, BE23) -> 0 | BH23: =SUM(D23, F23, H23, J23, L23, N23, P23, R23, T23, V23, X23, Z23, AB23, AD23, AF23, AH23, AJ23, AL23, AN23, AP23, AR23, AT23, AV23, AX23, AZ23, BB23, BD23, BF23) -> 0
A24: Ice Cream Van | C24: 280 | D24: 870 | E24: 250 | F24: 516 | BG24: =SUM(C24, E24, G24, I24, K24, M24, O24, Q24, S24, U24, W24, Y24, AA24, AC24, AE24, AG24, AI24, AK24, AM24, AO24, AQ24, AS24, AU24, AW24, AY24, BA24, BC24, BE24) -> 530 | BH24: =SUM(D24, F24, H24, J24, L24, N24, P24, R24, T24, V24, X24, Z24, AB24, AD24, AF24, AH24, AJ24, AL24, AN24, AP24, AR24, AT24, AV24, AX24, AZ24, BB24, BD24, BF24) -> 1386
A25: Total | C25: =SUM(C17:C24) -> 3045 | D25: =SUM(D17:D24) -> 10309 | E25: =SUM(E17:E24) -> 2530 | F25: =SUM(F17:F24) -> 9303 | G25: =SUM(G17:G24) -> 0 | H25: =SUM(H17:H24) -> 0 | I25: =SUM(I17:I24) -> 0 | J25: =SUM(J17:J24) -> 0 | ... BH25: =SUM(BH17:BH24) -> 19612
A28: Staff | C28: 45833 | E28: 45834 | G28: 45835 | I28: 45836 | K28: 45837 | M28: 45839 | O28: 45840 | Q28: 45841 | S28: 45842 | U28: 45843 | W28: 45845 | Y28: 45846 | AA28: 45847 | AC28: 45848 | AE28: 45849 | AG28: 45850 | AI28: 45851 | AK28: 45854 | AM28: 45855 | AO28: 45856 | AQ28: 45857 | AS28: 45858 | AU28: 45860 | AW28: 45861 | AY28: 45862 | BA28: 45863 | BC28: 45864 | BE28: 45865
C29: Picture This -Sold Out | E29: Picture This -Extra Date Added | G29: The Coronas | I29: Christy Moore -Sold Out | K29: Dara O‘Briain | M29: Joe Bonamassa Plays Rory Gallagher -Sold Out | O29: Joe Bonamassa Plays Rory Gallagher -Sold Out | Q29: Joe Bonamassa Plays Rory Gallagher -Extra Date | S29: Tommy Tiernan | U29: Tommy Tiernan - Sold Out | W29: Roy Keane and Roddy Doyle - Sold Out | Y29: Roy Keane and Roddy Doyle - Sold Out | AA29: Roy Keane and Roddy Doyle - Sold Out | AC29: The Waterboys | AE29: Chris Kent | AG29: Dec Pierce | AI29: Olly Murs | AK29: Kingfishr - Sold Out | AM29: Amble - Sold Out | AO29: The Mary Wallopers | AQ29: Cian Ducrot - Sold Out | AS29: Cian Ducrot | AU29: D-Block Europe | AW29: D-Block Europe - Sold Out | AY29: Kingfishr - Sold Out | BA29: Michael McIntyre - Sold Out | BC29: Michael McIntyre - Sold Out | BE29: Michael McIntyre - Sold Out
A30: Smash Burger | BG30: =SUM(C30, E30, G30, I30, K30, M30, O30, Q30, S30, U30, W30, Y30, AA30, AC30, AE30, AG30, AI30, AK30, AM30, AO30, AQ30, AS30, AU30, AW30, AY30, BA30, BC30, BE30) -> 0 | BH30: =SUM(D30, F30, H30, J30, L30, N30, P30, R30, T30, V30, X30, Z30, AB30, AD30, AF30, AH30, AJ30, AL30, AN30, AP30, AR30, AT30, AV30, AX30, AZ30, BB30, BD30, BF30) -> 0
A33: Pitt Bros BBQ | BG33: =SUM(C33, E33, G33, I33, K33, M33, O33, Q33, S33, U33, W33, Y33, AA33, AC33, AE33, AG33, AI33, AK33, AM33, AO33, AQ33, AS33, AU33, AW33, AY33, BA33, BC33, BE33) -> 0 | BH33: =SUM(D33, F33, H33, J33, L33, N33, P33, R33, T33, V33, X33, Z33, AB33, AD33, AF33, AH33, AJ33, AL33, AN33, AP33, AR33, AT33, AV33, AX33, AZ33, BB33, BD33, BF33) -> 0
A35: Franks Hot Dog | BG35: =SUM(C35, E35, G35, I35, K35, M35, O35, Q35, S35, U35, W35, Y35, AA35, AC35, AE35, AG35, AI35, AK35, AM35, AO35, AQ35, AS35, AU35, AW35, AY35, BA35, BC35, BE35) -> 0 | BH35: =SUM(D35, F35, H35, J35, L35, N35, P35, R35, T35, V35, X35, Z35, AB35, AD35, AF35, AH35, AJ35, AL35, AN35, AP35, AR35, AT35, AV35, AX35, AZ35, BB35, BD35, BF35) -> 0
A37: Angelo's Pizza | BG37: =SUM(C37, E37, G37, I37, K37, M37, O37, Q37, S37, U37, W37, Y37, AA37, AC37, AE37, AG37, AI37, AK37, AM37, AO37, AQ37, AS37, AU37, AW37, AY37, BA37, BC37, BE37) -> 0 | BH37: =SUM(D37, F37, H37, J37, L37, N37, P37, R37, T37, V37, X37, Z37, AB37, AD37, AF37, AH37, AJ37, AL37, AN37, AP37, AR37, AT37, AV37, AX37, AZ37, BB37, BD37, BF37) -> 0
A39: Kiosk | BG39: =SUM(C39, E39, G39, I39, K39, M39, O39, Q39, S39, U39, W39, Y39, AA39, AC39, AE39, AG39, AI39, AK39, AM39, AO39, AQ39, AS39, AU39, AW39, AY39, BA39, BC39, BE39) -> 0 | BH39: =SUM(D39, F39, H39, J39, L39, N39, P39, R39, T39, V39, X39, Z39, AB39, AD39, AF39, AH39, AJ39, AL39, AN39, AP39, AR39, AT39, AV39, AX39, AZ39, BB39, BD39, BF39) -> 0
A41: Caffe Duomo | BG41: =SUM(C41, E41, G41, I41, K41, M41, O41, Q41, S41, U41, W41, Y41, AA41, AC41, AE41, AG41, AI41, AK41, AM41, AO41, AQ41, AS41, AU41, AW41, AY41, BA41, BC41, BE41) -> 0 | BH41: =SUM(D41, F41, H41, J41, L41, N41, P41, R41, T41, V41, X41, Z41, AB41, AD41, AF41, AH41, AJ41, AL41, AN41, AP41, AR41, AT41, AV41, AX41, AZ41, BB41, BD41, BF41) -> 0
A43: Coca Cola Can | BG43: =SUM(C43, E43, G43, I43, K43, M43, O43, Q43, S43, U43, W43, Y43, AA43, AC43, AE43, AG43, AI43, AK43, AM43, AO43, AQ43, AS43, AU43, AW43, AY43, BA43, BC43, BE43) -> 0 | BH43: =SUM(D43, F43, H43, J43, L43, N43, P43, R43, T43, V43, X43, Z43, AB43, AD43, AF43, AH43, AJ43, AL43, AN43, AP43, AR43, AT43, AV43, AX43, AZ43, BB43, BD43, BF43) -> 0
A44: Ice Cream Van | BG44: =SUM(C44, E44, G44, I44, K44, M44, O44, Q44, S44, U44, W44, Y44, AA44, AC44, AE44, AG44, AI44, AK44, AM44, AO44, AQ44, AS44, AU44, AW44, AY44, BA44, BC44, BE44) -> 0 | BH44: =SUM(D44, F44, H44, J44, L44, N44, P44, R44, T44, V44, X44, Z44, AB44, AD44, AF44, AH44, AJ44, AL44, AN44, AP44, AR44, AT44, AV44, AX44, AZ44, BB44, BD44, BF44) -> 0
A45: Total | C45: =COUNTA(C30:D44) -> 0 | E45: =COUNTA(E30:F44) -> 0 | G45: =COUNTA(G30:H44) -> 0 | I45: =COUNTA(I30:J44) -> 0 | K45: =COUNTA(K30:L44) -> 0 | M45: =COUNTA(M30:N44) -> 0 | O45: =COUNTA(O30:P44) -> 0 | Q45: =COUNTA(Q30:R44) -> 0 | S45: =COUNTA(S30:T44) -> 0 | U45: =COUNTA(U30:V44) -> 0 | W45: =COUNTA(W30:X44) -> 0 | Y45: =COUNTA(Y30:Z44) -> 0 | AA45: =COUNTA(AA30:AB44) -> 0 | AC45: =COUNTA(AC30:AD44) -> 0 | AE45: =COUNTA(AE30:AF44) -> 0 | AG45: =COUNTA(AG30:AH44) -> 0 | AI45: =COUNTA(AI30:AJ44) -> 0 | AK45: =COUNTA(AK30:AL44) -> 0 | AM45: =COUNTA(AM30:AN44) -> 0 | AO45: =COUNTA(AO30:AP44) -> 0 | AQ45: =COUNTA(AQ30:AR44) -> 0 | AS45: =COUNTA(AS30:AT44) -> 0 | AU45: =COUNTA(AU30:AV44) -> 0 | AW45: =COUNTA(AW30:AX44) -> 0 | AY45: =COUNTA(AY30:AZ44) -> 0 | BA45: =COUNTA(BA30:BB44) -> 0 | BC45: =COUNTA(BC30:BD44) -> 0 | BE45: =COUNTA(BE30:BF44) -> 0 | BG45: =SUM(BG30:BG44) -> 0 | BH45: =SUM(BH30:BH44) -> 0

Sheet LATIG
A1: Live at the Marquee
A2: Stall/Unit Name | C2: 🅿️ | D2: 🧽 | E2: ⚡️ | F2: 🌡️ | G2: 💻
A3: Pizza Pasta | C3: FALSE | D3: FALSE | E3: FALSE | F3: FALSE | G3: FALSE | H3: FALSE
A4: Thindi | C4: FALSE | D4: FALSE | E4: FALSE | F4: FALSE | G4: FALSE | H4: FALSE
A5: Pitt Bros BBQ | C5: FALSE | D5: FALSE | E5: FALSE | F5: FALSE | G5: FALSE | H5: FALSE
A8: Takings | C8: 45841 | D8: 45842 | E8: 45844 | F8: 45849 | G8: 45850 | H8: 45851 | I8: 45855 | J8: 45856 | K8: 45857 | L8: 45858 | M8: 45839 | O8: 45840 | Q8: 45841 | S8: 45842 | U8: 45843
C9: Picture This -Sold Out | E9: Picture This -Extra Date Added | G9: The Coronas | I9: Christy Moore -Sold Out | K9: Dara O‘Briain | M9: Joe Bonamassa Plays Rory Gallagher -Sold Out | O9: Joe Bonamassa Plays Rory Gallagher -Sold Out | Q9: Joe Bonamassa Plays Rory Gallagher -Extra Date | S9: Tommy Tiernan | U9: Tommy Tiernan - Sold Out
C10: Cash | D10: Card | E10: Cash | F10: Card | G10: Cash | H10: Card | I10: Cash | J10: Card | K10: Cash | L10: Card | M10: Cash | N10: Card | O10: Cash | P10: Card | Q10: Cash | R10: Card | S10: Cash | T10: Card | U10: Cash | V10: Card
A11: Thindi
A12: Pitt Bros BBQ
A13: Total | C13: =SUM(C11:C12) -> 0 | D13: =SUM(D11:D12) -> 0 | E13: =SUM(E11:E12) -> 0 | F13: =SUM(F11:F12) -> 0 | G13: =SUM(G11:G12) -> 0 | H13: =SUM(H11:H12) -> 0 | I13: =SUM(I11:I12) -> 0 | J13: =SUM(J11:J12) -> 0 | ... V13: =SUM(V11:V12) -> 0
A16: Staff | C16: 45833 | E16: 45834 | G16: 45835 | I16: 45836 | K16: 45837 | M16: 45839 | O16: 45840 | Q16: 45841 | S16: 45842 | U16: 45843
C17: Picture This -Sold Out | E17: Picture This -Extra Date Added | G17: The Coronas | I17: Christy Moore -Sold Out | K17: Dara O‘Briain | M17: Joe Bonamassa Plays Rory Gallagher -Sold Out | O17: Joe Bonamassa Plays Rory Gallagher -Sold Out | Q17: Joe Bonamassa Plays Rory Gallagher -Extra Date | S17: Tommy Tiernan | U17: Tommy Tiernan - Sold Out
A18: Thindi
A21: Pitt Bros BBQ
A23: Total | C23: =COUNTA(C18:D22) -> 0 | E23: =COUNTA(E18:F22) -> 0 | G23: =COUNTA(G18:H22) -> 0 | I23: =COUNTA(I18:J22) -> 0 | K23: =COUNTA(K18:L22) -> 0 | M23: =COUNTA(M18:N22) -> 0 | O23: =COUNTA(O18:P22) -> 0 | Q23: =COUNTA(Q18:R22) -> 0 | S23: =COUNTA(S18:T22) -> 0 | U23: =COUNTA(U18:V22) -> 0

Sheet Rate Cards
B2: Rate Card
B3: Concept Name | C3: Cuisine / Theme | D3: Description | E3: Min. Daily Rate (€ ex. VAT) | F3: Min. Price Per Head (€)
B4: Camile Thai | C4: Thai Street Food | D4: Ireland’s top Thai food brand. Award-winning dishes & sustainability focus. | E4: 2750 | F4: 13.75
B5: Zambrero | C5: Mexican / Burrito Bowls | D5: Fast-growing global Mexican brand. Freshly made bowls, burritos, and nachos. | E5: 2500 | F5: 12.5
B6: Offbeat Donuts | C6: Artisan Donuts & Coffee | D6: Fresh daily donuts & coffee. Popular at both internal events and public gatherings. | E6: 1800 | F6: 9
B7: Pitt Bros BBQ | C7: American BBQ | D7: Smoked meats, BBQ sides. A crowd-pleasing option with a high volume service capacity. | E7: 2750 | F7: 13.75
B8: Thindi | C8: Indian Street Food | D8: Trendy Indian food from a restored French vintage truck. Colourful and flavour-packed. | E8: 2500 | F8: 12.5
B9: Sprinkles | C9: Loaded Churros / Desserts | D9: Churros and desserts concept, very popular with families and casual events. | E9: 1500 | F9: 9
B10: Desserts by Sprinkles | C10: Sweet Treats | D10: Expanded dessert concept from our Sprinkles brand – ideal for after-lunch or evening events. | E10: 1500 | F10: 9
B11: Caffe Duomo | C11: Coffee & Pastries | D11: Authentic Italian-style café concept. Great for breakfast activations and AM service. | E11: 1500 | F11: 7.5
